<?xml version="1.0" ?>
<sdf version="1.5">
  <model name="createiarcred">
    <link name="base">
      <inertial>
        <pose>0.001453 -0.000453 0.029787 0 0 0</pose>
        <inertia>
          <ixx>0.058640</ixx>
          <ixy>0.000124</ixy>
          <ixz>0.000615</ixz>
          <iyy>0.058786</iyy>
          <iyz>0.000014</iyz>
          <izz>1.532440</izz>
        </inertia>
        <mass>2.234000</mass>
      </inertial>
      <collision name="base_collision">
        <pose>0 0 0.047800 0 0 0</pose>
        <geometry>
          <cylinder>
            <radius>0.016495</radius>
            <length>0.061163</length>
          </cylinder>
        </geometry>
      </collision>
      <visual name="base_visual">
        <pose>0 0 0.047800 0 0 0</pose>
        <geometry>
          <mesh>
            <uri>model://createiarcred/meshes/create_body.dae</uri>
          </mesh>
        </geometry>
      </visual>
      <collision name="front_wheel_collision">
        <pose>0.130000 0 0.017000 0 1.570700 1.570700</pose>
        <geometry>
          <sphere>
            <radius>0.018000</radius>
          </sphere>
        </geometry>
        <surface>
          <friction>
            <ode>
              <mu>0</mu>
              <mu2>0</mu2>
              <fdir1>0 0 0</fdir1>
              <slip1>0</slip1>
              <slip2>0</slip2>
            </ode>
          </friction>
        </surface>
      </collision>
      <visual name="front_wheel_visual">
        <pose>0.130000 0 0.017000 0 1.570700 1.570700</pose>
        <geometry>
          <sphere>
            <radius>0.009000</radius>
          </sphere>
        </geometry>
      </visual>
      <collision name="rear_wheel_collision">
        <pose>-0.13 0 0.017 0 1.5707 1.5707</pose>
        <geometry>
          <sphere>
            <radius>0.015000</radius>
          </sphere>
        </geometry>
        <surface>
          <friction>
            <ode>
              <mu>0</mu>
              <mu2>0</mu2>
              <fdir1>0 0 0</fdir1>
              <slip1>0</slip1>
              <slip2>0</slip2>
            </ode>
          </friction>
        </surface>
      </collision>
      <visual name="rear_wheel_visual">
        <pose>-0.130000 0 0.017000 0 1.570700 1.570700</pose>
        <geometry>
          <sphere>
            <radius>0.007500</radius>
          </sphere>
        </geometry>
      </visual>
     
    </link>
    <link name="left_wheel">
      <pose>0 0.130000 0.032000 0 0 0</pose>
      <inertial>
        <inertia>
          <ixx>0.001000</ixx>
          <ixy>0</ixy>
          <ixz>0</ixz>
          <iyy>0.001000</iyy>
          <iyz>0</iyz>
          <izz>0.001000</izz>
        </inertia>
        <mass>0.010000</mass>
      </inertial>
      <collision name="collision">
        <pose>0 0 0 0 1.570700 1.570700</pose>
        <geometry>
          <cylinder>
            <radius>0.033000</radius>
            <length>0.023000</length>
          </cylinder>
        </geometry>
        <surface>
          <friction>
            <ode>
              <mu>10</mu>
              <mu2>10</mu2>
              <fdir1>0 0 0</fdir1>
              <slip1>0</slip1>
              <slip2>0</slip2>
            </ode>
          </friction>
        </surface>
      </collision>
      <visual name="visual">
        <pose>0 0 0 0 1.570700 1.570700</pose>
        <geometry>
          <cylinder>
            <radius>0.033000</radius>
            <length>0.023000</length>
          </cylinder>
        </geometry>
      </visual>
    </link>
    <link name="right_wheel">
      <pose>0 -0.130000 0.032000 0 0 0</pose>
      <inertial>
        <inertia>
          <ixx>0.001000</ixx>
          <ixy>0</ixy>
          <ixz>0</ixz>
          <iyy>0.001000</iyy>
          <iyz>0</iyz>
          <izz>0.001000</izz>
        </inertia>
        <mass>0.010000</mass>
      </inertial>
      <collision name="collision">
        <pose>0 0 0 0 1.570700 1.570700</pose>
        <geometry>
          <cylinder>
            <radius>0.033000</radius>
            <length>0.023000</length>
          </cylinder>
        </geometry>
        <surface>
          <friction>
            <ode>
              <mu>10</mu>
              <mu2>10</mu2>
              <fdir1>0 0 0</fdir1>
              <slip1>0</slip1>
              <slip2>0</slip2>
            </ode>
          </friction>
        </surface>
      </collision>
      <visual name="visual">
        <pose>0 0 0 0 1.570700 1.570700</pose>
        <geometry>
          <cylinder>
            <radius>0.033000</radius>
            <length>0.023000</length>
          </cylinder>
        </geometry>
      </visual>
    </link>
    <joint name="left_wheel" type="revolute">
      <parent>base</parent>
      <child>left_wheel</child>
      <axis>
        <xyz>0 1 0</xyz>
        <use_parent_model_frame>true</use_parent_model_frame>
      </axis>
    </joint>
    <joint name="right_wheel" type="revolute">
      <parent>base</parent>
      <child>right_wheel</child>
      <axis>
        <xyz>0 1 0</xyz>
        <use_parent_model_frame>true</use_parent_model_frame>
      </axis>
    </joint>

    <!-- Quadrotor dynamics and control -->
    <plugin name="UGV" filename="libsim_ugv.so">
      
      <!-- Everything will be applied to this link -->
      <link>base</link>

      <!-- Propulsion -->
      <groundforce>
        <dynamics>
          <low_throttle>300</low_throttle>
          <max_angvel>2.617993877991494</max_angvel>
          <pq0>-3.25060e-04</pq0>
          <pq1>1.79797e+02</pq1>
          <pq2>-24.3536</pq2>
          <r0>-4.81783e-03</r0>
          <r1>-5.08944</r1>
          <Cth0>6.63881e-01</Cth0>
          <Cth1>7.44649e-04</Cth1>
          <Cth2>2.39855e-06</Cth2>
          <Cvb0>-18.0007</Cvb0>
          <Cvb1>4.23754</Cvb1>
          <tau0>3.07321</tau0>
          <tau1>46.8004</tau1>
        </dynamics>
        <control>
          <roll>
            <scale>-2291.83118052329</scale>
            <min>-0.1</min>
            <max> 0.1</max>
          </roll>
          <pitch>
            <scale>-2291.83118052329</scale>
            <min>-0.1</min>
            <max> 0.1</max>
          </pitch>
          <yaw>
            <scale>-460.597254433196</scale>
            <min>-4.5</min>
            <max> 4.5</max>
          </yaw>
          <throttle>
            <scale>4097</scale>
            <min>0.0</min>
            <max>1.0</max>
          </throttle>
          <voltage>
            <scale>1.0</scale>
            <min> 9.0</min>
            <max>12.0</max>
          </voltage>
        </control>
        <errors>
          <force><white><sigma>0.2</sigma></white></force>
          <torque><white><sigma>0.2</sigma></white></torque>
        </errors>
      </groundforce>

      <!-- Energy parameters -->
      <energy>
        <remaining>6000</remaining>
        <consumption>
          <base>0.1</base>
          <flight>6.6</flight>
        </consumption>
        <limits>
          <warn>1000</warn>
          <land>100</land>
        </limits>
        <errors>
          <consumption><white><sigma>0.002</sigma></white></consumption>
        </errors>
      </energy>

      <!-- Drag parameters -->
      <aerodynamics>
        <shear>
          <ma>0.05</ma>
          <z0>0.15</z0>
        </shear>
        <drag>
          <kuv>-4.97391e-01</kuv>
          <kw>-1.35341</kw>
        </drag>
        <errors>
          <turbulence><dryden></dryden></turbulence>
        </errors>
      </aerodynamics>
      
      <!-- Altimeter parameters -->
      <altimeter>
        <errors>
          <altitude><ou><beta>300</beta><sigma>0.003</sigma></ou></altitude>
        </errors>
      </altimeter>

      <!-- Compass parameters -->
      <compass>
        <errors>
          <magnetic><white><sigma>0.02</sigma></white></magnetic>
        </errors>
      </compass>

      <!-- GNSS parameters -->
      <gnss>
        <solver>
          <minelevation>15</minelevation>
          <nsiterations>10</nsiterations>
          <errtolerance>3.e-7</errtolerance>
          <gps>
            <use>true</use>
            <ion>false</ion>
            <tro>false</tro>
            <eph>false</eph>
            <clk>false</clk>
          </gps>
          <glo>
            <use>false</use>
            <ion>false</ion>
            <tro>false</tro>
            <eph>false</eph>
            <clk>false</clk>
          </glo>
        </solver>
        <errors>
          <clock><white><sigma>0.02</sigma></white></clock>
        </errors>
      </gnss>

      <!-- IMU parameters -->
      <imu>
        <errors>
          <linacc><white><sigma>0.0025</sigma></white></linacc>
          <angvel><white><sigma>0.0002</sigma></white></angvel>
        </errors>
      </imu>

      <!-- Orientation parameters -->
      <orientation>
        <errors>
          <orientation><ou><beta>0.01</beta><sigma>0.0005</sigma></ou></orientation>
        </errors>
      </orientation>

    </plugin>

  </model>
</sdf>
